<?xml version="1.0" ?>
<sdf version="1.5">
  <model name="f1cart">
  <pose>0 0 0.05 0 0 0</pose> 
  <self_collide>false</self_collide>
  <plugin name="ca_cart_plugin" filename="libca_cart.so">
  </plugin>

    <link name="chassis">
      <pose>0 0 0 0 0 0</pose>
      <inertial>
        <mass>19.07</mass>    
        <pose> 0.0 0.0 0.0125 0.0 0.0 0.0</pose>
        <inertia>
          <ixx>0.29136</ixx>
          <ixy>-0.00036</ixy>
          <ixz>0</ixz>
          <iyy>1.58212</iyy>
          <iyz>0</iyz>
          <izz>1.29277</izz>
        </inertia>
      </inertial>
      <collision name="chassis_collision">
        <geometry>
          <mesh>
             <scale>1 1 1</scale>
             <uri>model://f1cart/Meshes/f1cart_body_colis.dae</uri>
          </mesh>
        </geometry>
        <surface>
            <bounce>
	            <restitution_coefficient>0.45</restitution_coefficient>
	            <threshold>0.01</threshold>
            </bounce>
        </surface>
      </collision>
      <visual name="chassis_visual">
        <cast_shadows>true</cast_shadows>
        <geometry>
          <mesh>
             <scale>1 1 1</scale>
             <uri>model://f1cart/Meshes/f1cart_body.dae</uri>
          </mesh>
        </geometry>
      </visual>
    </link> 
    
    <link name="kinect_cam">
      <gravity>false</gravity>
      <pose>-0.3 0 0.15 0 0.15 3.14</pose>
      <visual name="kinect_cam_visual">
        <geometry>
          <mesh>
            <uri>model://f1cart/Meshes/kinect.dae</uri>
          </mesh>
        </geometry>
      </visual>
      
      <sensor type="depth" name="openni_camera">      
        <always_on>1</always_on>
            <visualize>true</visualize>             
        <camera>
            <horizontal_fov>1.047</horizontal_fov>  
            <image>
                <width>640</width>
                <height>480</height>
                <format>R8G8B8</format>
            </image>
            <depth_camera>

            </depth_camera>
            <clip>
                <near>0.5</near>
                <far>5</far>
            </clip>
        </camera>
        <plugin name="camera_controller" filename="libgazebo_ros_openni_kinect.so">
            <alwaysOn>true</alwaysOn>
                <updateRate>10.0</updateRate>
                <cameraName>camera</cameraName>
                <frameName>kinect_cam</frameName>                   
            <imageTopicName>rgb/image_raw</imageTopicName>
            <depthImageTopicName>depth/image_raw</depthImageTopicName>
            <pointCloudTopicName>depth/points</pointCloudTopicName>
            <cameraInfoTopicName>rgb/camera_info</cameraInfoTopicName>              
            <depthImageCameraInfoTopicName>depth/camera_info</depthImageCameraInfoTopicName>            
            <pointCloudCutoff>0.4</pointCloudCutoff>                
                <hackBaseline>0.07</hackBaseline>
                <distortionK1>0.0</distortionK1>
                <distortionK2>0.0</distortionK2>
                <distortionK3>0.0</distortionK3>
                <distortionT1>0.0</distortionT1>
                <distortionT2>0.0</distortionT2>
            <CxPrime>0.0</CxPrime>
            <Cx>0.0</Cx>
            <Cy>0.0</Cy>
            <focalLength>0.0</focalLength>
            <robotNamespace>cart</robotNamespace>
        </plugin>
    </sensor>
    </link>
    
    <link name="rgb_cam">
      <gravity>false</gravity>
      <pose>0.3 0 0.1 0 0 0</pose>
      <visual name="rgb_cam_visual">
        <geometry>
          <box>
             <size>0.03 0.03 0.03</size>
          </box>
        </geometry>
      </visual>
      
      <sensor type = "camera" name ="rgb_sensor">
        <pose> 0 0 0 0 -0.6 3.14 </pose>
        <always_on>1 </always_on>
        <update_rate>30 </update_rate>
        <visualize> false </visualize>
        <camera>
          <horizontal_fov> 1.04700 </horizontal_fov>
          <image>
            <width>640 </width>
            <height>480 </height>
          </image>
          <clip>
            <near> 0.5 </near> // 1 mm
            <far> 25 </far> // 10 mm
          </clip>
        </camera>
        <!-- Attach plugin here -->
      </sensor> 
    </link>
    
    <joint type="fixed" name="rgb_cam_support">
      <child>rgb_cam</child>
      <parent>chassis</parent>
      <axis>
        <xyz>1 1 1</xyz>
        <use_parent_model_frame>true</use_parent_model_frame>
      </axis>
    </joint>
    
    <joint type="fixed" name="kinect_cam_support">
      <child>kinect_cam</child>
      <parent>chassis</parent>
      <axis>
        <xyz>1 1 1</xyz>
        <use_parent_model_frame>true</use_parent_model_frame>
      </axis>
    </joint>

    <include>
      <pose>0.37 -0.2125 0.0125 0 0 0</pose>
      <name>rl_wheel</name>
      <uri>model://f1cart/f1cart_wheel</uri>
    </include>

    <include>
      <pose>0.37 0.2125 0.0125 0 0 3.14</pose>
      <name>rr_wheel</name>
      <uri>model://f1cart/f1cart_wheel</uri>
    </include>

    <joint type="revolute" name="rl_wheel_joint">
      <child>rl_wheel::rim</child>
      <parent>chassis</parent>
      <axis>
        <xyz>0 1 0</xyz>
        <use_parent_model_frame>true</use_parent_model_frame>
      </axis>
    </joint>

    <joint type="revolute" name="rr_wheel_joint">
      <child>rr_wheel::rim</child>
      <parent>chassis</parent>
      <axis>
        <xyz>0 1 0</xyz>
        <use_parent_model_frame>true</use_parent_model_frame>
      </axis>
    </joint>
    
    <include>
      <pose>-0.36 -0.17 0.015 0 0 2.75</pose>
      <name>fl_wheel</name>
      <uri>model://f1cart/f1cart_small_wheel</uri>
    </include>

    <include>
      <pose>-0.36 0.17 0.015 0 0 2.75</pose>
      <name>fr_wheel</name>
      <uri>model://f1cart/f1cart_small_wheel</uri>
    </include>

    <joint type="revolute" name="fl_wheel_joint">
      <child>fl_wheel::tyre</child>
      <parent>chassis</parent>
      <axis>
        <xyz>0 1 0</xyz>
      </axis>
    </joint>

    <joint type="revolute" name="fr_wheel_joint">
      <child>fr_wheel::tyre</child>
      <parent>chassis</parent>
      <axis>
        <xyz>0 1 0</xyz>
      </axis>
    </joint>
   

  </model>
</sdf>
